<mujoco model="apptronik_apollo">
  <compiler angle="radian" meshdir="assets"/>

  <option timestep="0.005" integrator="implicitfast"/>

  <default>
    <default class="apollo">
      <site rgba="1 0 0 1" size="0.01" group="5"/>
      <joint limited="true"/>
      <geom contype="0" conaffinity="0" condim="1" group="1" solref="0.005" margin="0.0005"/>
      <equality solref="0.005" solimp="0.99 0.999 1e-05"/>
      <default class="active_adhesion">
        <geom margin="0.01" gap="0.01" rgba="0.8 0.5 0.5 1"/>
      </default>
      <default class="visual">
        <geom type="mesh"/>
        <default class="visual_dark">
          <geom rgba="0.0980392 0.0980392 0.0980392 1"/>
        </default>
        <default class="visual_light">
          <geom rgba="0.960784 0.960784 0.952941 1"/>
        </default>
      </default>
      <default class="collision">
        <geom contype="1" conaffinity="1" group="3" rgba="0 1 0 0.4"/>
      </default>
    </default>
  </default>

  <asset>
    <mesh name="neck_mount_fix_link" file="neck_mount_fix_link.stl"/>
    <mesh name="neck_yaw_link" file="neck_yaw_link.stl"/>
    <mesh name="afh_2_1_link" file="afh_2_1_link.stl"/>
    <mesh name="torso_link" file="torso_link.stl"/>
    <mesh name="battery_mount_fix" file="battery_mount_fix.stl"/>
    <mesh name="torso_pitch_link" file="torso_pitch_link.stl"/>
    <mesh name="torso_roll_link" file="torso_roll_link.stl"/>
    <mesh name="pelvis_link" file="pelvis_link.stl"/>
    <mesh name="l_shoulder_aa_link" file="l_shoulder_aa_link.stl"/>
    <mesh name="l_shoulder_ie_link" file="l_shoulder_ie_link.stl"/>
    <mesh name="l_shoulder_fe_link" file="l_shoulder_fe_link.stl"/>
    <mesh name="l_elbow_fe_link" file="l_elbow_fe_link.stl"/>
    <mesh name="l_wrist_roll_link" file="l_wrist_roll_link.stl"/>
    <mesh name="l_wrist_yaw_link" file="l_wrist_yaw_link.stl"/>
    <mesh name="l_wrist_pitch_link" file="l_wrist_pitch_link.stl"/>
    <mesh name="wrist_adapter" file="ability_hand/wrist_adapter.STL"/>
    <mesh name="wristmesh" file="ability_hand/wristmesh.STL"/>
    <mesh name="FB_palm_ref" file="ability_hand/FB_palm_ref.STL"/>
    <mesh name="idx-F1" file="ability_hand/idx-F1.STL"/>
    <mesh name="idx-F2" file="ability_hand/idx-F2.STL"/>
    <mesh name="thumb-F1" file="ability_hand/thumb-F1.STL"/>
    <mesh name="thumb-F2-left" file="ability_hand/thumb-F2-left.STL"/>
    <mesh name="r_shoulder_aa_link" file="r_shoulder_aa_link.stl"/>
    <mesh name="r_shoulder_ie_link" file="r_shoulder_ie_link.stl"/>
    <mesh name="r_shoulder_fe_link" file="r_shoulder_fe_link.stl"/>
    <mesh name="r_elbow_fe_link" file="r_elbow_fe_link.stl"/>
    <mesh name="r_wrist_roll_link" file="r_wrist_roll_link.stl"/>
    <mesh name="r_wrist_yaw_link" file="r_wrist_yaw_link.stl"/>
    <mesh name="r_wrist_pitch_link" file="r_wrist_pitch_link.stl"/>
    <mesh name="FB_palm_ref_MIR" file="ability_hand/FB_palm_ref_MIR.STL"/>
    <mesh name="thumb-F1-MIR" file="ability_hand/thumb-F1-MIR.STL"/>
    <mesh name="thumb-F2-right" file="ability_hand/thumb-F2-right.STL"/>
    <mesh name="l_hip_ie_link" file="l_hip_ie_link.stl"/>
    <mesh name="l_hip_aa_link" file="l_hip_aa_link.stl"/>
    <mesh name="l_hip_fe_link" file="l_hip_fe_link.stl"/>
    <mesh name="l_knee_fe_link" file="l_knee_fe_link.stl"/>
    <mesh name="l_ankle_ie_link" file="l_ankle_ie_link.stl"/>
    <mesh name="l_foot_link" file="l_foot_link.stl"/>
    <mesh name="r_hip_ie_link" file="r_hip_ie_link.stl"/>
    <mesh name="r_hip_aa_link" file="r_hip_aa_link.stl"/>
    <mesh name="r_hip_fe_link" file="r_hip_fe_link.stl"/>
    <mesh name="r_knee_fe_link" file="r_knee_fe_link.stl"/>
    <mesh name="r_ankle_ie_link" file="r_ankle_ie_link.stl"/>
    <mesh name="r_foot_link" file="r_foot_link.stl"/>
  </asset>

  <worldbody>
    <light pos="0 0 3" dir="0 0 -1" diffuse="0.2 0.2 0.2" mode="trackcom"/>
    <body name="base_link" pos="0 0 1.0813" childclass="apollo">
      <inertial pos="-0.0466459 -2.50736e-05 -0.0721416" quat="0.661991 0.662086 0.248682 -0.248127" mass="7.43582" diaginertia="0.0633318 0.0512326 0.0281854"/>
      <joint name="floating_base" type="free" limited="false" actuatorfrclimited="false"/>
      <geom class="visual_light" mesh="pelvis_link"/>
      <geom name="collision_capsule_body_pelvis" class="collision" size="0.1 0.09" pos="-0.06 0 -0.08" quat="0.707388 0.706825 0 0" type="capsule"/>
      <camera name="track" pos="1.69 -2.93 1.232" quat="0.791164 0.554139 0.148485 0.211997" mode="trackcom"/>
      <body name="torso_oak_d_pro_w_rear_frame_link" pos="-0.164306 5e-08 0.0140886" quat="0.000689634 -0.500011 0.000398172 0.866019">
        <inertial pos="0 0 0" mass="0.115" diaginertia="0.000144423 3.89011e-05 0.000126395"/>
        <camera name="torso_oak_d_pro_w_rear" pos="0 0 0" quat="0.500398 0.5 -0.499602 -0.5" fovy="70"/>
      </body>
      <body name="torso_oak_d_pro_w_front_frame_link" pos="0.087306 -5e-08 0.0480886" quat="0.866025 0 0.500001 0">
        <inertial pos="0 0 0" mass="0.115" diaginertia="0.000144423 3.89011e-05 0.000126395"/>
        <camera name="torso_oak_d_pro_w_front" pos="0 0 0" quat="0.500398 0.5 -0.499602 -0.5" fovy="70"/>
      </body>
      <body name="torso_roll_link" pos="0.03 0 0.03125">
        <inertial pos="-0.0337439 7.47864e-09 -0.0199137" quat="0.5297 0.511275 -0.470427 0.486532" mass="0.824114" diaginertia="0.00159405 0.00123171 0.000760001"/>
        <joint name="torso_yaw" pos="0 0 0" axis="0 0 -1" range="-0.829031 0.829031" actuatorfrcrange="-120 120" armature="0.231424" damping="11.7" frictionloss="0.7"/>
        <geom class="visual_dark" mesh="torso_roll_link"/>
        <body name="torso_pitch_link">
          <inertial pos="-0.0120797 5.39687e-05 -0.00065376" quat="0.49026 0.489868 -0.50995 0.509534" mass="0.313137" diaginertia="0.000415493 0.000345069 9.17604e-05"/>
          <joint name="torso_roll" pos="0 0 0" axis="1 0 0" range="-0.20944 0.20944" actuatorfrcrange="-414 414" armature="1.56493" frictionloss="4.53"/>
          <geom class="visual_dark" mesh="torso_pitch_link"/>
          <body name="torso_link">
            <inertial pos="-0.0484952 0.00143204 0.185535" quat="0.702792 0.0157426 -6.68569e-05 0.711221" mass="19.3408" diaginertia="0.303595 0.272287 0.22035"/>
            <joint name="torso_pitch" pos="0 0 0" axis="0 1 0" range="-0.305433 1.35263" actuatorfrcrange="-315 315" armature="0.970692" frictionloss="13.15"/>
            <geom class="visual_light" mesh="torso_link"/>
            <geom name="collision_cylinder_torso" class="collision" size="0.16 0.05" pos="-0.045 0 0.2" type="capsule"/>
            <geom class="visual_dark" mesh="neck_mount_fix_link"/>
            <geom class="visual_dark" mesh="battery_mount_fix"/>
            <site name="imu" pos="0.037 0 0.093624" quat="9.38184e-07 0.707105 9.38187e-07 -0.707108"/>
            <body name="neck_yaw_link" pos="-0.0303298 0 0.32841" quat="0.991445 0 0.130526 0">
              <site name="head" pos="0 0 .3" size="0.02"/>
              <inertial pos="-0.0110616 0.000438589 0.066541" quat="0.715974 -0.0707674 -0.0795701 0.689958" mass="0.707753" diaginertia="0.00278981 0.002738 0.00071974"/>
              <joint name="neck_yaw" pos="0 0 0" axis="0 0 1" range="-1.65806 1.65806" actuatorfrcrange="-10.6 10.6" armature="0.0368" damping="10"/>
              <geom name="neck_yaw_geom" class="visual_dark" mesh="neck_yaw_link"/>
              <body name="neck_roll_link" pos="-0.025 0 0.2" quat="1.32679e-06 -1 0 0">
                <inertial pos="9.66662e-05 -0.000233736 -0.000463806" quat="0.000426355 0.703652 0.00178423 0.710542" mass="0.0189001" diaginertia="1.89727e-06 1.24254e-06 1.0322e-06"/>
                <joint name="neck_roll" pos="0 0 0" axis="1 0 0" range="-0.785398 0.785398" actuatorfrcrange="-34.2 34.2" armature="0.00305531" damping="10"/>
                <body name="neck_pitch_link" quat="1.17527e-06 0.885799 6.15724e-07 -0.464069">
                  <inertial pos="0.0412474 -0.00081671 0.0152493" quat="0.350337 0.613318 0.617311 0.346457" mass="1.78084" diaginertia="0.0135957 0.0109432 0.00697581"/>
                  <joint name="neck_pitch" pos="0 0 0" axis="0 1 0" range="-0.261799 0.523599" actuatorfrcrange="-34.2 34.2" armature="0.00256298" damping="10"/>
                  <geom class="visual_light" pos="0 0 0" quat="0.938794 0 0.344479 0" mesh="afh_2_1_link"/>
                </body>
              </body>
            </body>
            <body name="l_shoulder_aa_link" pos="-0.05 0.2 0.32">
              <inertial pos="0.000169922 0.0025177 -0.0190065" quat="0.710165 -0.0144759 0.023056 0.703508" mass="0.0980048" diaginertia="4.61576e-05 3.97046e-05 1.43504e-05"/>
              <joint name="l_shoulder_aa" pos="0 0 0" axis="1 0 0" range="-0.122173 1.6057" actuatorfrcrange="-78 78" armature="0.0982771" damping="12.2" frictionloss="2"/>
              <geom class="visual_dark" mesh="l_shoulder_aa_link"/>
              <body name="l_shoulder_ie_link">
                <inertial pos="-0.00799772 0.0154729 -0.0231746" quat="0.0914838 0.586016 -0.671384 0.444364" mass="0.451281" diaginertia="0.00069896 0.000628486 0.000278066"/>
                <joint name="l_shoulder_ie" pos="0 0 0" axis="0 0 1" range="-0.471239 0.471239" actuatorfrcrange="-67 67" armature="0.0823104" damping="17.7" frictionloss="1.48"/>
                <geom class="visual_dark" mesh="l_shoulder_ie_link"/>
                <body name="l_shoulder_fe_link" pos="0.0104822 0.03912 0" quat="0.991445 0 0 -0.130526">
                  <inertial pos="0.00453031 0.00134632 -0.143556" quat="0.707095 0.0140891 -0.00274087 0.706973" mass="3.51271" diaginertia="0.0284589 0.0232812 0.00763948"/>
                  <joint name="l_shoulder_fe" pos="0 0 0" axis="0 1 0" range="-2.18166 0.610865" actuatorfrcrange="-114 114" armature="0.112768" frictionloss="1.94"/>
                  <geom class="visual_light" mesh="l_shoulder_fe_link"/>
                  <geom name="collision_capsule_body_l_arm_1" class="collision" size="0.055 0.14" pos="-0.005 0.01 -0.16" type="capsule"/>
                  <geom name="collision_capsule_body_l_arm_2" class="collision" size="0.055 0.055" pos="0.05 0.005 -0.125" type="capsule"/>
                  <geom name="collision_capsule_body_l_arm_3" class="collision" size="0.055 0.02" pos="-0.06 0.0025 -0.13" type="capsule"/>
                  <body name="l_elbow_fe_link" pos="0.025 0 -0.315">
                    <inertial pos="-0.0407636 -0.000100019 -0.0277184" quat="0.446501 0.557407 0.539502 0.445951" mass="0.947642" diaginertia="0.00105876 0.000944065 0.00076124"/>
                    <joint name="l_elbow_fe" pos="0 0 0" axis="0 1 0" range="-2.61799 0.174533" actuatorfrcrange="-114 114" armature="0.102645" frictionloss="2.55"/>
                    <geom class="visual_dark" mesh="l_elbow_fe_link"/>
                    <body name="l_wrist_roll_link" pos="-0.04 0 -0.06" quat="0.707105 0 0 0.707108">
                      <inertial pos="0.0088493 0.000434657 -0.071867" quat="0.701782 -0.0503482 -0.0435035 0.709278" mass="0.694478" diaginertia="0.00294512 0.00284275 0.000723985"/>
                      <joint name="l_wrist_roll" pos="0 0 0" axis="0 0 1" range="-1.65806 1.65806" actuatorfrcrange="-10.6 10.6" armature="0.0368" damping="10"/>
                      <geom class="visual_light" mesh="l_wrist_roll_link"/>
                      <geom name="collision_cylinder_l_arm" class="collision" size="0.04755 0.1076" pos="0 0 -0.1" type="capsule"/>
                      <body name="l_wrist_yaw_link" pos="0.025 0 -0.2">
                        <inertial pos="-9.66662e-05 0.000233736 -0.000463806" quat="-0.00178423 0.710542 -0.000426355 0.703652" mass="0.0189001" diaginertia="1.89727e-06 1.24254e-06 1.0322e-06"/>
                        <joint name="l_wrist_yaw" pos="0 0 0" axis="1 0 0" range="-0.698 0.698" actuatorfrcrange="-34.2 34.2" armature="0.00329371" damping="10"/>
                        <geom class="visual_dark" mesh="l_wrist_yaw_link"/>
                        <body name="l_wrist_pitch_link" quat="0.707105 0 0 -0.707108">
                          <inertial pos="0.0071177 -0.038442 -0.0669519" quat="0.614861 0.00892233 0.0323416 0.787921" mass="0.806883" diaginertia="0.00459474 0.00452816 0.00206219"/>
                          <joint name="l_wrist_pitch" pos="0 0 0" axis="1 0 0" range="-0.75 1.588" actuatorfrcrange="-34.2 34.2" armature="0.00288074" damping="10"/>
                          <geom class="visual_dark" mesh="l_wrist_pitch_link"/>
                          <geom name="wrist_adapter_mesh" class="visual_dark" pos="0 -0.0297676 -0.0277946" quat="1 0 0 0" mesh="wrist_adapter"/>
                          <geom name="wrist_mesh" class="visual_dark" pos="0 -0.0343657 -0.0392954" quat="0.130526 0.991445 0 0" mesh="wristmesh"/>
                          <geom name="palm_mesh" class="visual_dark" pos="0.0240477 -0.0463856 -0.0695448" quat="0.00516808 0.0439309 0.130372 0.990478" mesh="FB_palm_ref"/>
                          <geom name="index_mesh_1" class="visual_dark" pos="0.0279216 -0.0502244 -0.134299" quat="0.0355504 -0.725304 0.0429902 0.686165" mesh="idx-F1"/>
                          <geom name="index_mesh_2" class="visual_dark" pos="0.0296624 -0.053984 -0.172686" quat="0.00654576 -0.722842 0.0735774 0.687054" mesh="idx-F2"/>
                          <geom name="middle_mesh_1" class="visual_dark" pos="0.00841718 -0.0488804 -0.137964" quat="0.0114639 -0.705931 0.0210022 0.707876" mesh="idx-F1"/>
                          <geom name="middle_mesh_2" class="visual_dark" pos="0.00814998 -0.0526507 -0.176389" quat="-0.018436 -0.704415 0.0507911 0.707729" mesh="idx-F2"/>
                          <geom name="ring_mesh_1" class="visual_dark" pos="-0.0117529 -0.049354 -0.135394" quat="-0.0126044 -0.685391 -0.0036555 0.728057" mesh="idx-F1"/>
                          <geom name="ring_mesh_2" class="visual_dark" pos="-0.0139914 -0.0531239 -0.173755" quat="-0.0433349 -0.684934 0.025288 0.726875" mesh="idx-F2"/>
                          <geom name="pinky_mesh_1" class="visual_dark" pos="-0.0308633 -0.0509308 -0.128792" quat="-0.0350419 -0.683018 -0.0274385 0.729045" mesh="idx-F1"/>
                          <geom name="pinky_mesh_2" class="visual_dark" pos="-0.0330569 -0.0546993 -0.167156" quat="-0.0657942 -0.683567 0.00142601 0.726915" mesh="idx-F2"/>
                          <geom name="thumb_mesh_1" class="visual_dark" pos="0.0240477 -0.0463856 -0.0695448" quat="-0.986553 0.125649 -0.0560269 -0.0882391" mesh="thumb-F1"/>
                          <geom name="thumb_mesh_2" class="visual_dark" pos="0.0499644 -0.0457352 -0.0874305" quat="0.500891 -0.859176 -0.0358978 0.0981657" mesh="thumb-F2-left"/>
                          <!-- <geom name="collision_l_hand_plate" class="collision" size="0.041 0.02 0.083" pos="0.00749988 -0.025 -0.112" type="box"/> -->
                          <geom name="collision_l_hand_plate" class="collision" size="0.055 0.083" pos="0.00749988 -0.04 -0.112" type="capsule"/>
                          <site name="left_palm" pos="0 -0.05 -.08"/>
                        </body>
                      </body>
                    </body>
                  </body>
                </body>
              </body>
            </body>
            <body name="r_shoulder_aa_link" pos="-0.05 -0.2 0.32">
              <inertial pos="0.000169922 0.0025177 -0.0190065" quat="0.710165 -0.0144759 0.023056 0.703508" mass="0.0980048" diaginertia="4.61576e-05 3.97046e-05 1.43504e-05"/>
              <joint name="r_shoulder_aa" pos="0 0 0" axis="1 0 0" range="-1.6057 0.122173" actuatorfrcrange="-78 78" armature="0.098338" damping="12.9" frictionloss="2"/>
              <geom class="visual_dark" mesh="r_shoulder_aa_link"/>
              <body name="r_shoulder_ie_link">
                <inertial pos="-0.00800045 -0.0154894 -0.0231814" quat="0.583857 0.0885889 -0.445504 0.672897" mass="0.451079" diaginertia="0.000700361 0.00062725 0.000277886"/>
                <joint name="r_shoulder_ie" pos="0 0 0" axis="0 0 1" range="-0.471239 0.471239" actuatorfrcrange="-67 67" armature="0.0823191" damping="17.7" frictionloss="1.48"/>
                <geom class="visual_dark" mesh="r_shoulder_ie_link"/>
                <body name="r_shoulder_fe_link" pos="0.0104822 -0.03912 0" quat="0.991445 0 0 0.130526">
                  <inertial pos="0.00420186 -0.00125575 -0.142983" quat="0.7032 -0.00225527 0.011754 0.710892" mass="3.50359" diaginertia="0.0282519 0.0230724 0.00763457"/>
                  <joint name="r_shoulder_fe" pos="0 0 0" axis="0 1 0" range="-2.18166 0.610865" actuatorfrcrange="-114 114" armature="0.112768" frictionloss="1.94"/>
                  <geom class="visual_light" mesh="r_shoulder_fe_link"/>
                  <geom name="collision_capsule_body_r_arm_1" class="collision" size="0.055 0.14" pos="-0.005 -0.01 -0.16" type="capsule"/>
                  <geom name="collision_capsule_body_r_arm_2" class="collision" size="0.055 0.055" pos="0.05 -0.005 -0.125" type="capsule"/>
                  <geom name="collision_capsule_body_r_arm_3" class="collision" size="0.055 0.02" pos="-0.06 -0.0025 -0.13" type="capsule"/>
                  <body name="r_elbow_fe_link" pos="0.025 0 -0.315">
                    <inertial pos="-0.0407591 0.000134025 -0.0277185" quat="0.458533 0.527215 0.568785 0.433907" mass="0.947653" diaginertia="0.00105948 0.000943838 0.000761313"/>
                    <joint name="r_elbow_fe" pos="0 0 0" axis="0 1 0" range="-2.61799 0.174533" actuatorfrcrange="-114 114" armature="0.102645" frictionloss="2.55"/>
                    <geom class="visual_dark" mesh="r_elbow_fe_link"/>
                    <body name="r_wrist_roll_link" pos="-0.04 0 -0.06" quat="0.707105 0 0 -0.707108">
                      <inertial pos="0.00887138 -0.000263913 -0.0718159" quat="0.698707 -0.0449538 -0.0486448 0.712336" mass="0.695137" diaginertia="0.00294733 0.00284457 0.000724756"/>
                      <joint name="r_wrist_roll" pos="0 0 0" axis="0 0 1" range="-1.65806 1.65806" actuatorfrcrange="-10.6 10.6" armature="0.0368" damping="10"/>
                      <geom class="visual_light" mesh="r_wrist_roll_link"/>
                      <geom name="collision_cylinder_r_arm" class="collision" size="0.04755 0.1076" pos="0 0 -0.1" type="capsule"/>
                      <body name="r_wrist_yaw_link" pos="0.025 0 -0.2" quat="1.32679e-06 0 0 -1">
                        <inertial pos="9.66662e-05 0.000233736 -0.000463806" quat="-0.00044002 0.703652 -0.00179716 0.710542" mass="0.0189001" diaginertia="1.89727e-06 1.24254e-06 1.0322e-06"/>
                        <joint name="r_wrist_yaw" pos="0 0 0" axis="1 0 0" range="-0.698 0.698" actuatorfrcrange="-34.2 34.2" armature="0.0032937" damping="10"/>
                        <geom class="visual_dark" mesh="r_wrist_yaw_link"/>
                        <body name="r_wrist_pitch_link" quat="0.707105 0 0 -0.707108">
                          <inertial pos="0.0181202 0.0388729 -0.0688824" quat="0.630263 -0.0221958 -0.0501406 0.774443" mass="0.806683" diaginertia="0.00526208 0.00452156 0.0026899"/>
                          <joint name="r_wrist_pitch" pos="0 0 0" axis="1 0 0" range="-1.588 0.75" actuatorfrcrange="-34.2 34.2" armature="0.00288075" damping="10"/>
                          <geom class="visual_dark" mesh="r_wrist_pitch_link"/>
                          <geom class="visual_dark" pos="0 0.0297676 -0.0277946" quat="1.32679e-06 0 0 1" mesh="wrist_adapter"/>
                          <geom class="visual_dark" pos="1.22016e-08 0.0343657 -0.0392954" quat="1.73181e-07 1.31544e-06 0.991445 0.130526" mesh="wristmesh"/>
                          <geom class="visual_dark" pos="0.0240477 0.0463855 -0.0695448" quat="0.990478 0.130372 0.0439307 0.00516677" mesh="FB_palm_ref_MIR"/>
                          <geom class="visual_dark" pos="0.0279216 0.0502243 -0.134299" quat="0.725304 -0.0355495 0.686165 0.0429892" mesh="idx-F1"/>
                          <geom class="visual_dark" pos="0.0296625 0.053984 -0.172686" quat="0.722842 -0.00654484 0.687054 0.0735764" mesh="idx-F2"/>
                          <geom class="visual_dark" pos="0.00841723 0.0488804 -0.137964" quat="0.705931 -0.0114629 0.707876 0.0210013" mesh="idx-F1"/>
                          <geom class="visual_dark" pos="0.00815005 0.0526507 -0.176389" quat="0.704415 0.018437 0.707729 0.0507901" mesh="idx-F2"/>
                          <geom class="visual_dark" pos="-0.0117529 0.0493541 -0.135394" quat="0.685391 0.0126053 0.728057 -0.00365641" mesh="idx-F1"/>
                          <geom class="visual_dark" pos="-0.0139913 0.053124 -0.173755" quat="0.684934 0.0433359 0.726875 0.0252871" mesh="idx-F2"/>
                          <geom class="visual_dark" pos="-0.0308632 0.0509308 -0.128792" quat="0.683018 0.0350429 0.729045 -0.0274394" mesh="idx-F1"/>
                          <geom class="visual_dark" pos="-0.0330568 0.0546993 -0.167156" quat="0.683567 0.0657951 0.726915 0.00142511" mesh="idx-F2"/>
                          <geom class="visual_dark" pos="0.0240477 0.0463855 -0.0695448" quat="-0.125649 0.986553 -0.0882404 -0.0560268" mesh="thumb-F1-MIR"/>
                          <geom class="visual_dark" pos="0.0499644 0.0457351 -0.0874305" quat="-0.859175 0.500891 -0.0981665 0.0358989" mesh="thumb-F2-right"/>
                          <geom name="collision_r_hand_plate" class="collision" size="0.055 0.083" pos="0.00749988 0.04 -0.112" type="capsule"/>
                          <site name="right_palm" pos="0 0.05 -.08"/>
                        </body>
                      </body>
                    </body>
                  </body>
                </body>
              </body>
            </body>
          </body>
        </body>
      </body>
      <body name="l_hip_ie_link" pos="-0.02 0.11 -0.16875" quat="0.957662 0.126078 -0.256605 0.0337826">
        <inertial pos="-0.0275726 0.000155527 0.0265849" quat="-0.0182885 0.43376 -0.029543 0.900358" mass="1.49972" diaginertia="0.00446385 0.00343018 0.00205254"/>
        <joint name="l_hip_ie" pos="0 0 0" axis="0 0 1" range="-0.567232 1.09083" actuatorfrcrange="-120 120" armature="0.231424" frictionloss="7.95"/>
        <geom class="visual_dark" mesh="l_hip_ie_link"/>
        <body name="l_hip_aa_link">
          <inertial pos="0.000193883 0.00068757 0.00240456" quat="0.488822 0.400587 -0.484645 0.604733" mass="0.429858" diaginertia="0.000370659 0.000322451 0.000129015"/>
          <joint name="l_hip_aa" pos="0 0 0" axis="1 0 0" range="-0.218166 0.741765" actuatorfrcrange="-494 494" armature="0.399395" frictionloss="7"/>
          <geom class="visual_dark" mesh="l_hip_aa_link"/>
          <body name="l_hip_fe_link" quat="0.957662 -0.126079 0.256605 -0.0337828">
            <inertial pos="0.0065559 0.00346415 -0.207233" quat="0.864334 0.00804176 0.0489557 0.500466" mass="10.7833" diaginertia="0.124113 0.120556 0.0499696"/>
            <joint name="l_hip_fe" pos="0 0 0" axis="0 1 0" range="-1.85005 0.476475" actuatorfrcrange="-342 342" armature="0.187096" damping="20.31" frictionloss="21.06"/>
            <geom class="visual_light" mesh="l_hip_fe_link"/>
            <geom name="collision_capsule_body_l_thigh" class="collision" size="0.105 0.1" pos="0 0.005 -0.215" type="capsule"/>
            <body name="l_knee_fe_link" pos="-0.05 0 -0.425">
              <inertial pos="0.043534 0.00505054 -0.152417" quat="0.917057 0.00954505 0.0113608 0.398479" mass="4.57515" diaginertia="0.0639569 0.0630895 0.0108036"/>
              <joint name="l_knee_fe" pos="0 0 0" axis="0 1 0" range="0 2.61799" actuatorfrcrange="-336 336" armature="0.292264" frictionloss="7.7"/>
              <geom class="visual_light" mesh="l_knee_fe_link"/>
              <geom name="collision_capsule_body_l_shin" class="collision" size="0.071 0.15" pos="0.0476 0.0061 -0.19" quat="0.998048 0 0.0624593 0" type="capsule"/>
              <body name="l_ankle_ie_link" pos="0.05 0 -0.425" quat="0.987672 0.0864102 -0.130029 0.0113761">
                <inertial pos="0.00995038 9.93144e-05 0.000832075" quat="0.692933 0.691803 0.145013 -0.14221" mass="0.12478" diaginertia="4.80038e-05 4.18024e-05 1.66067e-05"/>
                <joint name="l_ankle_ie" pos="0 0 0" axis="1 0 0" range="-0.654498 0.305433" actuatorfrcrange="-120 120" armature="0.121874" frictionloss="0.89"/>
                <geom class="visual_dark" mesh="l_ankle_ie_link"/>
                <body name="l_foot_link" quat="0.965926 0 0.258819 0">
                  <inertial pos="0.056607 -0.00200339 -0.0304112" quat="0.432893 0.587516 0.510475 0.454802" mass="1.1808" diaginertia="0.0088235 0.00838261 0.00210633"/>
                  <joint name="l_ankle_pd" pos="0 0 0" axis="0 1 0" range="-1.5708 0.436332" actuatorfrcrange="-150 150" armature="0.205456" damping="9.11" frictionloss="1.87"/>
                  <geom class="visual_dark" mesh="l_foot_link"/>
                  <geom name="collision_l_sole" class="collision" size="0.1 0.0425 0.009" pos="0.0646931 -0.00550529 -0.03843" quat="0.987443 -0.0797175 -0.132426 -0.0326442" type="box"/>
                  <site name="left_foot" pos="0.0614891 -0.00342931 -0.0265273" quat="0.987443 -0.0797175 -0.132426 -0.0326442"/>
                </body>
              </body>
            </body>
          </body>
        </body>
      </body>
      <body name="r_hip_ie_link" pos="-0.02 -0.11 -0.16875" quat="0.957662 -0.126078 -0.256605 -0.0337826">
        <inertial pos="-0.0275542 -0.000156081 0.0265869" quat="0.0347714 0.433956 0.0469856 0.899036" mass="1.49972" diaginertia="0.00446281 0.00343307 0.00204473"/>
        <joint name="r_hip_ie" pos="0 0 0" axis="0 0 1" range="-1.09083 0.567232" actuatorfrcrange="-120 120" armature="0.231424" frictionloss="7.95"/>
        <geom class="visual_dark" mesh="r_hip_ie_link"/>
        <body name="r_hip_aa_link">
          <inertial pos="0.000193891 -0.000687548 0.00240456" quat="0.469753 0.583843 -0.513458 0.418115" mass="0.429858" diaginertia="0.000369398 0.000323696 0.000129031"/>
          <joint name="r_hip_aa" pos="0 0 0" axis="1 0 0" range="-0.741765 0.218166" actuatorfrcrange="-494 494" armature="0.399396" frictionloss="7"/>
          <geom class="visual_dark" mesh="r_hip_aa_link"/>
          <body name="r_hip_fe_link" quat="0.957662 0.126079 0.256605 0.0337828">
            <inertial pos="0.00662296 -0.00380822 -0.207131" quat="0.493002 0.049361 0.00782621 0.868591" mass="10.7924" diaginertia="0.124314 0.120603 0.0499318"/>
            <joint name="r_hip_fe" pos="0 0 0" axis="0 1 0" range="-1.85005 0.476475" actuatorfrcrange="-342 342" armature="0.187096" damping="20.31" frictionloss="21.06"/>
            <geom class="visual_light" mesh="r_hip_fe_link"/>
            <geom name="collision_capsule_body_r_thigh" class="collision" size="0.105 0.1" pos="0 -0.005 -0.215" type="capsule"/>
            <body name="r_knee_fe_link" pos="-0.05 0 -0.425">
              <inertial pos="0.0432854 -0.00516245 -0.152442" quat="0.399848 0.0111994 0.00899692 0.916469" mass="4.57434" diaginertia="0.063915 0.0630953 0.0107961"/>
              <joint name="r_knee_fe" pos="0 0 0" axis="0 1 0" range="0 2.61799" actuatorfrcrange="-336 336" armature="0.292264" frictionloss="7.7"/>
              <geom class="visual_light" mesh="r_knee_fe_link"/>
              <geom name="collision_capsule_body_r_shin" class="collision" size="0.071 0.15" pos="0.0476 0.0061 -0.19" quat="0.998048 0 0.0624593 0" type="capsule"/>
              <body name="r_ankle_ie_link" pos="0.05 0 -0.425" quat="0.987672 -0.0864102 -0.130029 -0.0113761">
                <inertial pos="0.00995037 -9.921e-05 0.000832071" quat="0.69181 0.692928 0.142207 -0.145006" mass="0.12478" diaginertia="4.80035e-05 4.18021e-05 1.66065e-05"/>
                <joint name="r_ankle_ie" pos="0 0 0" axis="1 0 0" range="-0.305433 0.654498" actuatorfrcrange="-120 120" armature="0.121874" frictionloss="0.89"/>
                <geom class="visual_dark" mesh="r_ankle_ie_link"/>
                <body name="r_foot_link" quat="0.965926 0 0.258819 0">
                  <inertial pos="0.056607 0.00200339 -0.0304112" quat="0.414902 0.606299 0.487904 0.471389" mass="1.1808" diaginertia="0.00883289 0.00837251 0.00210704"/>
                  <joint name="r_ankle_pd" pos="0 0 0" axis="0 1 0" range="-1.5708 0.436332" actuatorfrcrange="-150 150" armature="0.205456" damping="9.11" frictionloss="1.87"/>
                  <geom class="visual_dark" mesh="r_foot_link"/>
                  <geom name="collision_r_sole" class="collision" size="0.1 0.0425 0.009" pos="0.0646931 0.00550529 -0.03843" quat="0.987443 0.0797175 -0.132426 0.0326442" type="box"/>
                  <site name="right_foot" pos="0.0614891 0.00342931 -0.0265273" quat="0.987443 0.0797175 -0.132426 0.0326442"/>
                </body>
              </body>
            </body>
          </body>
        </body>
      </body>
    </body>
    <body name="world_link"/>
  </worldbody>

  <contact>
    <exclude body1="r_wrist_pitch_link" body2="r_wrist_roll_link"/>
    <exclude body1="r_shoulder_fe_link" body2="r_wrist_roll_link"/>
    <exclude body1="l_wrist_pitch_link" body2="l_wrist_roll_link"/>
    <exclude body1="l_shoulder_fe_link" body2="l_wrist_roll_link"/>
  </contact>

  <actuator>
    <general class="apollo" name="neck_yaw" joint="neck_yaw" ctrlrange="-1.65806 1.65806" forcerange="-10.6 10.6" biastype="affine" gainprm="28" biasprm="0 -28 -15"/>
    <general class="apollo" name="neck_roll" joint="neck_roll" ctrlrange="-0.785398 0.785398" forcerange="-34.2 34.2" biastype="affine" gainprm="9" biasprm="0 -9 -3"/>
    <general class="apollo" name="neck_pitch" joint="neck_pitch" ctrlrange="-0.261799 0.523599" forcerange="-34.2 34.2" biastype="affine" gainprm="8" biasprm="0 -8 -3"/>
    <general class="apollo" name="torso_pitch" joint="torso_pitch" ctrlrange="-0.305433 1.35263" forcerange="-315 315" biastype="affine" gainprm="1525" biasprm="0 -1525 -142"/>
    <general class="apollo" name="torso_roll" joint="torso_roll" ctrlrange="-0.20944 0.20944" forcerange="-414 414" biastype="affine" gainprm="2052" biasprm="0 -2052 -165"/>
    <general class="apollo" name="torso_yaw" joint="torso_yaw" ctrlrange="-0.829031 0.829031" forcerange="-120 120" biastype="affine" gainprm="600" biasprm="0 -600 -60"/>
    <general class="apollo" name="l_hip_ie" joint="l_hip_ie" ctrlrange="-0.567232 1.09083" forcerange="-120 120" biastype="affine" gainprm="595" biasprm="0 -595 -171"/>
    <general class="apollo" name="l_hip_aa" joint="l_hip_aa" ctrlrange="-0.218166 0.741765" forcerange="-494 494" biastype="affine" gainprm="1880" biasprm="0 -1880 -153"/>
    <general class="apollo" name="l_hip_fe" joint="l_hip_fe" ctrlrange="-1.85005 0.476475" forcerange="-342 342" biastype="affine" gainprm="1047" biasprm="0 -1047 -92"/>
    <general class="apollo" name="l_knee_fe" joint="l_knee_fe" ctrlrange="0 2.61799" forcerange="-336 336" biastype="affine" gainprm="606" biasprm="0 -606 -46"/>
    <general class="apollo" name="l_ankle_ie" joint="l_ankle_ie" ctrlrange="-0.654498 0.305433" forcerange="-120 120" biastype="affine" gainprm="420" biasprm="0 -420 -11"/>
    <general class="apollo" name="l_ankle_pd" joint="l_ankle_pd" ctrlrange="-1.5708 0.436332" forcerange="-150 150" biastype="affine" gainprm="882" biasprm="0 -882 -21"/>
    <general class="apollo" name="r_hip_ie" joint="r_hip_ie" ctrlrange="-1.09083 0.567232" forcerange="-120 120" biastype="affine" gainprm="595" biasprm="0 -595 -171"/>
    <general class="apollo" name="r_hip_aa" joint="r_hip_aa" ctrlrange="-0.741765 0.218166" forcerange="-494 494" biastype="affine" gainprm="1880" biasprm="0 -1880 -153"/>
    <general class="apollo" name="r_hip_fe" joint="r_hip_fe" ctrlrange="-1.85005 0.476475" forcerange="-342 342" biastype="affine" gainprm="1047" biasprm="0 -1047 -92"/>
    <general class="apollo" name="r_knee_fe" joint="r_knee_fe" ctrlrange="0 2.61799" forcerange="-336 336" biastype="affine" gainprm="606" biasprm="0 -606 -46"/>
    <general class="apollo" name="r_ankle_ie" joint="r_ankle_ie" ctrlrange="-0.305433 0.654498" forcerange="-120 120" biastype="affine" gainprm="420" biasprm="0 -420 -11"/>
    <general class="apollo" name="r_ankle_pd" joint="r_ankle_pd" ctrlrange="-1.5708 0.436332" forcerange="-150 150" biastype="affine" gainprm="882" biasprm="0 -882 -21"/>
    <general class="apollo" name="l_shoulder_aa" joint="l_shoulder_aa" ctrlrange="-0.122173 1.6057" forcerange="-78 78" biastype="affine" gainprm="395" biasprm="0 -395 -26"/>
    <general class="apollo" name="l_shoulder_ie" joint="l_shoulder_ie" ctrlrange="-0.471239 0.471239" forcerange="-67 67" biastype="affine" gainprm="530" biasprm="0 -530 -45"/>
    <general class="apollo" name="l_shoulder_fe" joint="l_shoulder_fe" ctrlrange="-2.18166 0.610865" forcerange="-114 114" biastype="affine" gainprm="277" biasprm="0 -277 -21"/>
    <general class="apollo" name="l_elbow_fe" joint="l_elbow_fe" ctrlrange="-2.61799 0.174533" forcerange="-114 114" biastype="affine" gainprm="312" biasprm="0 -312 -24"/>
    <general class="apollo" name="l_wrist_roll" joint="l_wrist_roll" ctrlrange="-1.65806 1.65806" forcerange="-10.6 10.6" biastype="affine" gainprm="47" biasprm="0 -47 -15"/>
    <general class="apollo" name="l_wrist_yaw" joint="l_wrist_yaw" ctrlrange="-0.785398 0.785398" forcerange="-34.2 34.2" biastype="affine" gainprm="20" biasprm="0 -20 -3"/>
    <general class="apollo" name="l_wrist_pitch" joint="l_wrist_pitch" ctrlrange="-0.837758 1.67552" forcerange="-34.2 34.2" biastype="affine" gainprm="18" biasprm="0 -18 -3"/>
    <general class="apollo" name="r_shoulder_aa" joint="r_shoulder_aa" ctrlrange="-1.6057 0.122173" forcerange="-78 78" biastype="affine" gainprm="395" biasprm="0 -395 -26"/>
    <general class="apollo" name="r_shoulder_ie" joint="r_shoulder_ie" ctrlrange="-0.471239 0.471239" forcerange="-67 67" biastype="affine" gainprm="530" biasprm="0 -530 -45"/>
    <general class="apollo" name="r_shoulder_fe" joint="r_shoulder_fe" ctrlrange="-2.18166 0.610865" forcerange="-114 114" biastype="affine" gainprm="277" biasprm="0 -277 -21"/>
    <general class="apollo" name="r_elbow_fe" joint="r_elbow_fe" ctrlrange="-2.61799 0.174533" forcerange="-114 114" biastype="affine" gainprm="312" biasprm="0 -312 -24"/>
    <general class="apollo" name="r_wrist_roll" joint="r_wrist_roll" ctrlrange="-1.65806 1.65806" forcerange="-10.6 10.6" biastype="affine" gainprm="47" biasprm="0 -47 -15"/>
    <general class="apollo" name="r_wrist_yaw" joint="r_wrist_yaw" ctrlrange="-0.785398 0.785398" forcerange="-34.2 34.2" biastype="affine" gainprm="20" biasprm="0 -20 -3"/>
    <general class="apollo" name="r_wrist_pitch" joint="r_wrist_pitch" ctrlrange="-1.67552 0.837758" forcerange="-34.2 34.2" biastype="affine" gainprm="18" biasprm="0 -18 -3"/>
  </actuator>

  <sensor>
    <framequat objtype="site" objname="imu" name="IMU-orientation"/>
    <gyro site="imu" name="IMU-angular-velocity" cutoff="54.9" noise="0.0005"/>
    <accelerometer site="imu" name="IMU-linear-acceleration" cutoff="157" noise="0.0001"/>
    <magnetometer site="imu" name="IMU-magnetometer"/>
  </sensor>

  <keyframe>
    <key name="stand" qpos="0 0 1.01597 1 0 0 0 0 0 0 0 0 0 0.2 0 0.1 -0.4 0 0 0 -0.2 0 0.1 -0.4 0 0 0 0.08 0.1 -0.477 1.033 -0.03 -0.58 -0.08 -0.1 -0.477 1.033 0.03 -0.58" ctrl="0 0 0 0 0 0 0.08 0.1 -0.477 1.033 -0.03 -0.58 -0.08 -0.1 -0.477 1.033 0.03 -0.58 0.2 0 0.1 -0.4 0 0 0 -0.2 0 0.1 -0.4 0 0 0"/>
  </keyframe>
</mujoco>
